Workbook
Name _1610914392: 'ICT Cost'!$B$3
Name _1663400178: 'ICT Cost'!$B$25
Name Backup: #REF!
Name ChaiData: #REF!
Name ChaiPOS: #REF!
Name email: #REF!
Name Excel_BuiltIn_Print_Area_5_1: #REF!
Name Excel_BuiltIn_Print_Area_6: #REF!
Name Factory: #REF!
Name Farmers: #REF!
Name finance: #REF!
Name Financials: #REF!
Name Fleet: #REF!
Name Infrastructure: #REF!
Name KTDARegions: #REF!
Name OLE_LINK1: 'ICT Cost'!#REF!
Name Services: #REF!

Sheet Infrastructure and Systems
B1: Regions 1-7
B2: Region 1 | M2: 45930
A3: No. | B3: Item | C3: KAMBAA | D3: KAGWE | E3: THETA | F3: NDARUGU | G3: GACHEGE | H3: MATAARA | I3: NGERE | J3: NJUNU | K3: MAKOS | L3: NDUTI | M3: IKUMBI | N3: GACHARAGE
A4: 1 | B4: Local Area Network (LAN) | C4: LAN Upgrade completed | D4: LAN Upgrade not done | E4: LAN Upgrade not done | F4: LAN Upgrade not done | G4: LAN Upgrade not done | H4: LAN Upgrade not done | I4: LAN Upgrade completed | J4: LAN Upgrade not done | K4: LAN Upgrade not done | L4: LAN Upgrade not done | M4: LAN Upgrade completed | N4: LAN Upgrade not done
A5: 2 | B5: Wide Area Network (WAN) | C5: on Last mile Fibre | D5: Microwave-Viable on last mile Fibre | E5: Microwave-Viable on last mile Fibre | F5: on Last mile Fibre | G5: Microwave-Viable on last mile Fibre | H5: Microwave-Viable on last mile Fibre | I5: on Microwave | J5: on Microwave | K5: Microwave-Viable on last mile Fibre | L5: on Microwave | M5: Microwave-Viable on last mile Fibre | N5: on Microwave
A6: 3 | B6: Safaricom Backup VPN Line Status | C6: ok | D6: ok | E6: ok | F6: ok | G6: ok | H6: ok | I6: ok | J6: ok | K6: ok | L6: ok | M6: ok | N6: ok
A7: 4 | B7: Firewall | C7: Sophos License Expired | D7: Sophos License Expired | E7: Sophos License Valid | F7: Sophos License Valid | G7: Sophos License Expired | H7: Sophos License Expired | I7: Sophos License Expired | J7: Sophos License Expired | K7: Sophos License Expired | L7: Sophos License Expired | M7: Sophos License Expired | N7: Sophos License Expired
A8: 5 | B8: E-Mail Server | C8: Lotus Domino | D8: Lotus Domino | E8: Lotus Domino | F8: Lotus Domino | G8: Lotus Domino | H8: Lotus Domino | I8: Lotus Domino | J8: Lotus Domino | K8: Lotus Domino | L8: Lotus Domino | M8: Lotus Domino | N8: Lotus Domino
A9: 6 | B9: Business Servers (EWS, Chaipro) | C9: Working | D9: Working | E9: Working | F9: Working | G9: Working | H9: Working | I9: Working | J9: Working | K9: Working | L9: Working | M9: Working | N9: Working
A10: 7 | B10: Electronic Weighment Solution (EWS Version) | C10: 1.0.52 | D10: 1.0.52 | E10: 1.0.52 | F10: 1.0.52 | G10: 1.0.52 | H10: 1.0.52 | I10: 1.0.52 | J10: 1.0.57 | K10: 1.0.52 | L10: 1.0.52 | M10: 1.0.52 | N10: 1.0.52
A11: 8 | B11: EWS Kits | C11: EWS Kits10+ 2 Spare Kits | D11: EWS Kits 9+ 2 Spare Kits | E11: EWS Kits 7+ 2 Spare Kits | F11: EWS Kits 7+ 1 Spare Kits | G11: EWS Kits 8+ 2 Spare Kits | H11: EWS Kits 8+ 2 Spare Kits | I11: EWS Kits15+ 1 Spare Kit | J11: EWS Kits 7+ 1 Spare Kit | K11: EWS Kits14+ 1 Spare Kits | L11: EWS Kits 6+ 1 Spare Kit | M11: EWS Kits10+ 2 Spare Kits | N11: EWS Kits 8+ 1 Spare Kit
A12: 9 | B12: Printer (NFC Card & DFX) | C12: Fully Operational | D12: Fully Operational | E12: Fully Operational | F12: Fully Operational | G12: Fully Operational | H12: Fully Operational | I12: Fully Operational | J12: Fully Operational | K12: Fully Operational | L12: Fully Operational | M12: Fully Operational | N12: Fully Operational
A13: 10 | B13: WeighBridge Status | C13: Fully Operational | D13: Fully Operational | E13: Fully Operational | F13: Fully Operational | G13: Fully Operational | H13: Weighbridge not Installed | I13: Fully Operational | J13: Fully Operational | K13: Fully Operational | L13: Fully Operational | M13: Fully Operational | N13: Fully Operational
A14: 11 | B14: CCTV | C14: NVR has issues of hanging and thus having issues with retrieving data. | D14: 30 CAMERAS WORKING OK.3 CAMERAS UNDER REPAIR. | E14: CCTV is not functional – Faulty NVR and 2 cameras | F14: OK- no of cameras-25 and 20working\ 5not working | G14: Fully Operational | H14: 17 CAMERA NOT WORKING DUE TO ONGOING CONTRUCTION DEMOLISION OF OLD STORE | I14: NOT ADEQUATE- Request sent via RICTM to KTDA security manager for CCTV Assessment for additional cameras and repair of faulty ones | J14: Request for upgrade done by KTDA security Manager and RICTM | K14: 32 cameras installed 29 working | L14: 32 cameras 28 working 4 faulty | M14: 41 CAMERAS IN OPERATION | N14: Operational, 5 Cameras not working. Needs an Upgrade
A15: 12 | B15: SAP Connection (PRD,PSM) | C15: WORKING OK | D15: WORKING OK | E15: WORKING OK | F15: WORKING OK | G15: WORKING OK | H15: WORKING OK | I15: WORKING OK | J15: WORKING OK | K15: WORKING OK | L15: WORKING OK | M15: WORKING OK | N15: WORKING OK
A16: 13 | B16: AFMS | C16: Not Installed | D16: Installed | E16: Not Installed | F16: Not Installed | G16: Not Installed | H16: Not Installed | I16: Not Installed | J16: Not Installed | K16: Not Installed | L16: Not Installed | M16: Not Installed | N16: Not Installed
A17: 14 | B17: Any other
B19: Region 2
A20: No. | B20: Item | C20: Ragati | D20: Gathuthi | E20: Gitugi | F20: Iriaini | G20: Chinga | H20: Kiru | I20: Gatunguru | J20: Kanyenyaini | K20: Githambo
A21: 1 | B21: Local Area Network (LAN) | C21: No Issue Reported | D21: No Issue Reported | E21: No Issue Reported | F21: No Issue Reported | G21: No Issue Reported | H21: No Issue Reported | I21: No Issue Reported | J21: No Issue Reported | K21: No Issue Reported
A22: 2 | B22: Wide Area Network (WAN) | C22: No Issue Reported | D22: No Issue Reported | E22: No Issue Reported | F22: No Issue Reported | G22: No Issue Reported | H22: No Issue Reported | I22: No Issue Reported | J22: No Issue Reported | K22: No Issue Reported
A23: 3 | B23: Safaricom Backup VPN Line Status | C23: No Issue Reported | D23: No Issue Reported | E23: No Issue Reported | F23: No Issue Reported | G23: No Issue Reported | H23: No Issue Reported | I23: No Issue Reported | J23: No Issue Reported | K23: No Issue Reported
A24: 4 | B24: Firewall | C24: Domino in Use | D24: Domino in Use | E24: Domino in Use | F24: Domino in Use | G24: Domino in Use | H24: Domino in Use | I24: Domino in Use | J24: Domino in Use | K24: Domino in Use
A25: 5 | B25: E-Mail Server | C25: No Issue Reported | D25: No Issue Reported | E25: No Issue Reported | F25: No Issue Reported | G25: No Issue Reported | H25: No Issue Reported | I25: No Issue Reported | J25: No Issue Reported | K25: No Issue Reported
A26: 6 | B26: Business Servers (EWS, Chaipro) | C26: No Issue Reported | D26: No Issue Reported | E26: No Issue Reported | F26: No Issue Reported | G26: No Issue Reported | H26: No Issue Reported | I26: No Issue Reported | J26: No Issue Reported | K26: No Issue Reported
A27: 7 | B27: Electronic Weighment Solution (EWS Version) | C27: No Issue Reported | D27: No Issue Reported | E27: No Issue Reported | F27: No Issue Reported | G27: No Issue Reported | H27: No Issue Reported | I27: No Issue Reported | J27: No Issue Reported | K27: No Issue Reported
A28: 8 | B28: EWS Kits | C28: No Issue Reported | D28: No Issue Reported | E28: No Issue Reported | F28: No Issue Reported | G28: No Issue Reported | H28: No Issue Reported | I28: No Issue Reported | J28: No Issue Reported | K28: No Issue Reported
A29: 9 | B29: Printer (NFC Card & DFX) | C29: No Issue Reported | D29: No Issue Reported | E29: No Issue Reported | F29: No Issue Reported | G29: No Issue Reported | H29: No Issue Reported | I29: No Issue Reported | J29: No Issue Reported | K29: No Issue Reported
A30: 10 | B30: WeighBridge Status | C30: No Issue Reported | D30: No Issue Reported | E30: No Issue Reported | F30: No Issue Reported | G30: No Issue Reported | H30: No Issue Reported | I30: No Issue Reported | J30: No Issue Reported | K30: No Issue Reported
A31: 11 | B31: CCTV | C31: No Issue Reported | D31: No Issue Reported | E31: No Issue Reported | F31: No Issue Reported | G31: No Issue Reported | H31: No Issue Reported | I31: No Issue Reported | J31: No Issue Reported | K31: No Issue Reported
A32: 12 | B32: SAP Connection (PRD,PSM) | C32: No Issue Reported | D32: No Issue Reported | E32: No Issue Reported | F32: No Issue Reported | G32: No Issue Reported | H32: No Issue Reported | I32: No Issue Reported | J32: No Issue Reported | K32: No Issue Reported
... A34: 14 | B34: Any other | C34: None | D34: None | E34: None | F34: None | G34: None | H34: None | I34: None | J34: None | K34: None
B36: Region 3
A37: No. | B37: Item | C37: Ndima | D37: Mununga | E37: Kangaita | F37: Kimunye | G37: Thumaita | H37: Kathangariri | I37: Mungania | J37: Rukuriri
A38: 1 | B38: Local Area Network (LAN) | C38: Working OK Cat5 | D38: Working OK Cat 6 | E38: Working OK Cat5 | F38: Working OK Cat6 | G38: Working OK Cat6 | H38: Working OK Cat5 | I38: Working OK Cat5
A39: 2 | B39: Wide Area Network (WAN) | C39: Working OK | D39: Working OK | E39: Working OK | F39: Working OK | G39: Working OK | H39: Working OK | I39: Working OK
A40: 3 | B40: Safaricom Backup VPN Line Status | C40: Working OK | D40: Working OK | E40: OK | F40: Ok | G40: OKAY | H40: Working well | I40: Working OK
A41: 4 | B41: Firewall | C41: NO FIREWALL | D41: Working OK | E41: OK | F41: Ok | G41: N/A | H41: NOT WORKING | I41: Working OK
A42: 5 | B42: E-Mail Server | C42: Working OK | D42: Working OK | E42: OK though space needs to be increased | F42: Ok | G42: OKAY | H42: Working well | I42: Working OK
A43: 6 | B43: Business Servers (EWS, Chaipro) | C43: Working OK | D43: Working OK | E43: OK | F43: Ok | G43: OKAY | H43: Working well | I43: Working OK
...

Sheet Chaipro-SAP
B1: Region 1 | G1: ='Infrastructure and Systems'!M2 -> 45930
A2: No. | B2: Item | C2: KAMBAA | D2: KAGWE | E2: THETA | F2: NDARUGU | G2: GACHEGE | H2: MATAARA | I2: NGERE | J2: NJUNU | K2: MAKOS | L2: NDUTI | M2: IKUMBI | N2: GACHARAGE
A3: 1 | B3: Chaipro Financials | C3: SAP Module-FICO/MM | D3: SAP Module-FICO/MM | E3: SAP Module-FICO/MM | F3: SAP Module-FICO/MM | G3: SAP Module-FICO/MM | H3: SAP Module-FICO/MM | I3: SAP Module-FICO/MM | J3: SAP Module-FICO/MM | K3: SAP Module-FICO/MM | L3: SAP Module-FICO/MM | M3: SAP Module-FICO/MM | N3: SAP Module-FICO/MM
A4: 2 | B4: Chaipro Factory/TVAP | C4: SAP Module-PP/PM | D4: SAP Module-PP/PM | E4: SAP Module-PP/PM | F4: SAP Module-PP/PM | G4: SAP Module-PP/PM | H4: SAP Module-PP/PM | I4: SAP Module-PP/PM | J4: SAP Module-PP/PM | K4: SAP Module-PP/PM | L4: SAP Module-PP/PM | M4: SAP Module-PP/PM | N4: SAP Module-PP/PM
A5: 3 | B5: Chaipro Farmers | C5: 2.8.0.0 | D5: 2.8.0.0 | E5: 2.8.0.0 | F5: 2.8.0.0 | G5: 2.8.0.0 | H5: 2.8.0.0 | I5: 2.8.0.0 | J5: 2.8.0.0 | K5: 2.8.0.0 | L5: 2.8.0.0 | M5: 2.8.0.0 | N5: 2.8.0.0
A6: 4 | B6: Chaipro Fleet | C6: 3.2.5.1 | D6: 3.2.5.1 | E6: 3.2.5.1 | F6: 3.2.5.1 | G6: 3.2.5.1 | H6: 3.2.5.1 | I6: 3.2.5.1 | J6: 3.2.5.1 | K6: 3.2.5.1 | L6: 3.2.5.1 | M6: 3.2.5.1 | N6: 3.2.5.1
A7: 6 | B7: KTDA Replicator | C7: Version 10 fully operational | D7: Version 10 fully operational | E7: Version 10 fully operational | F7: Version 10 fully operational | G7: Version 10 fully operational | H7: Version 10 fully operational | I7: Version 10 fully operational | J7: Version 10 fully operational | K7: Version 10 fully operational | L7: Version 10 fully operational | M7: Version 10 fully operational | N7: Version 10 fully operational
A8: 7 | B8: Chai Data | C8: 1.0.0.3 | D8: 1.0.0.3 | E8: 1.0.0.3 | F8: 1.0.0.3 | G8: 1.0.0.3 | H8: 1.0.0.3 | I8: 1.0.0.3 | J8: 1.0.0.3 | K8: 1.0.0.3 | L8: 1.0.0.3 | M8: 1.0.0.3 | N8: 1.0.0.3
A9: 8 | B9: ETR Device | C9: OPERATIONAL | D9: OPERATIONAL | E9: OPERATIONAL | F9: OPERATIONAL | G9: OPERATIONAL | H9: OPERATIONAL | I9: OPERATIONAL | J9: OPERATIONAL | K9: OPERATIONAL | L9: OPERATIONAL | M9: OPERATIONAL | N9: OPERATIONAL
A10: 9 | B10: SMS Portal/USSD (Date growers received) | C10: 3rd October | D10: 3rd October | E10: 3rd October | F10: 3rd October | G10: 3rd October | H10: 3rd October | I10: 3rd October | J10: 3rd October | K10: 3rd October | L10: 3rd October | M10: 3rd October | N10: 3rd October
A11: 10 | B11: % NFC Card Usage | C11: 1 | D11: 1 | E11: 1 | F11: 1 | G11: 1 | H11: 1 | I11: 1 | J11: 1 | K11: 1 | L11: 1 | M11: 1 | N11: 1
B13: Region 2
A14: No. | B14: Item | C14: Ragati | D14: Gathuthi | E14: Gitugi | F14: Iriaini | G14: Chinga | H14: Kiru | I14: Gatunguru | J14: Kanyenyaini | K14: Githambo
A15: 1 | B15: Chaipro Financials | C15: 2.5.5.8 -fully utilized. | D15: 2.5.5.8 -fully utilized. | E15: 2.5.5.8 -fully utilized. | F15: 2.5.5.8 -fully utilized. | G15: 2.5.5.8 -fully utilized. | H15: 2.5.5.8 -fully utilized. | I15: 2.5.5.8-fully utilized. | J15: 2.5.5.8 -fully utilized. | K15: 2.5.5.8 -fully utilized.
A16: 2 | B16: Chaipro Factory/TVAP | C16: 2.5.2.7 - fully utilized. | D16: 2.5.2.7 - fully utilized. | E16: 2.5.2.7 - fully utilized. | F16: 2.5.2.7 - fully utilized. | G16: 2.5.2.7 - fully utilized. | H16: 2.5.2.7 - fully utilized. | I16: 2.5.2.7 - fully utilized. | J16: 2.5.2.7 - fully utilized. | K16: 2.5.2.7 - fully utilized.
A17: 3 | B17: Chaipro Farmers | C17: 2.8.0.0 - fully utilized. | D17: 2.8.0.0 - fully utilized. | E17: 2.8.0.0 - fully utilized. | F17: 2.8.0.0 - fully utilized. | G17: 2.8.0.0 - fully utilized. | H17: 2.8.0.0 - fully utilized. | I17: 2.8.0.0 - fully utilized. | J17: 2.8.0.0 - fully utilized. | K17: 2.8.0.0 - fully utilized.
A19: 4 | B19: Chaipro Fleet | C19: 3.2.5.1 - fully utilized. | D19: 3.2.5.1 - fully utilized. | E19: 3.2.5.1 - fully utilized. | F19: 3.2.5.1 - fully utilized. | G19: 3.2.5.1 - fully utilized. | H19: 3.2.5.1 - fully utilized. | I19: 3.2.5.1 - fully utilized. | J19: 3.2.5.1 - fully utilized. | K19: 3.2.5.1 - fully utilized.
A20: 6 | B20: KTDA Replicator | C20: Functional. | D20: Fully utilized. | E20: Fully utilized. | F20: Fully utilized. | G20: Fully utilized. | H20: Fully utilized. | I20: Fully utilized. | J20: Fully utilized. | K20: Fully utilized.
A21: 7 | B21: Chai Data | C21: 1.0.0.3 - fully utilized. | D21: 1.0.0.3 - fully utilized. | E21: 1.0.0.3 - fully utilized. | F21: 1.0.0.3 - fully utilized. | G21: 1.0.0.3 - fully utilized. | H21: 1.0.0.3 - fully utilized. | I21: 1.0.0.3 - fully utilized. | J21: 1.0.0.3 - fully utilized. | K21: 1.0.0.3 - fully utilized.
A22: 8 | B22: ETR Device
A23: 9 | B23: SMS Portal/USSD (Date growers received)
A24: 10 | B24: % NFC Card Usage
B26: Region 3
A27: No. | B27: Item | C27: NDIMA | D27: MUNUNGA | E27: KANGAITA | F27: Tombe | G27: KIMUNYE | H27: THUMAITA | I27: KATHANGARIRI | J27: MUNGANIA | K27: RUKURIRI
A28: 1 | B28: Chaipro Financials | C28: 2.5.5.9 | D28: 2.5.5.9 | E28: 2.5.5.9……not in use, we are On SAP | F28: 2.5.6.0 (Legacy) | G28: Okay - Ver. 2.5.5.9 | H28: Okay - Ver. 2.5.5.9 | I28: Partially Used | J28: 2.5.6.0 (Legacy) | K28: Fully on SAP
A29: 2 | B29: Chaipro Factory/ TVAP | C29: 2.5.2.7 | D29: 2.5.2.7 | E29: 2.5.2.7…… partially utilized | F29: 2.5.2.7 (Legacy) | G29: Okay - 2.5.2.7 | H29: Okay - 2.5.2.7 | I29: OK | J29: 2.5.2.7 (Legacy) | K29: Fully on SAP
A30: 3 | B30: Chaipro Farmers | C30: 3.0.0.1 | D30: 3.0.0.1 | E30: Fully utilized | F30: 3.0.0.1 (Fully Utilized) | G30: Okay - 3.0.0.1 | H30: Okay - 3.0.0.1 | I30: OK | J30: 3.0.0.1 (Fully Utilized) | K30: 3.0.0.1 - fully utilized.
A31: 4 | B31: Chaipro Fleet | C31: 3.2.5.1 | D31: 3.2.5.1 | E31: 3.2.5.1 partially utilized | F31: 3.2.1.1 (Legacy) | G31: Okay - 3.2.5.1 | H31: Okay - 3.2.5.1 | I31: Partially Used | J31: 3.2.1.1 (Legacy) | K31: 3.2.5.1 - Partly utilized.
A32: 6 | B32: KTDA Replicator | C32: 0.0.0.1 | D32: 0.0.0.1 | E32: Fully utilized | F32: 010 Fully Utilized | G32: Okay | H32: Okay | I32: OK | J32: 010 Fully Utilized | K32: fully utilized.
A33: 7 | B33: Chai Data | C33: ok | D33: replication software installed and working ok | E33: N/a | F33: 1.0.0.3 (Legacy) | G33: Okay | H33: Okay | I33: OK | J33: 1.0.0.3 (Legacy) | K33: Fully on SAP
A34: 8 | B34: ETR Device | C34: OK | D34: OK | E34: OK | F34: 2 pcs – Utilized 1 pc – under repair | G34: Okay | H34: Okay | I34: OK | J34: 2 pcs – Utilized 1 pc – under repair | K34: New TIMS ETR in use
A35: 9 | B35: SMS Portal/USSD (Date growers received) | C35: 3rd Oct | D35: 3rd Oct | E35: 2.10.2025 | F35: 2025-09-02 – Utilized | G35: 3rd Oct | H35: 3rd Oct | I35: OK | J35: 2025-09-02 – Utilized | K35: 3rd Oct
A36: 10 | B36: % NFC Card Usage | C36: 1 | D36: 1 | E36: 1 | F36: 1 | G36: 1 | H36: 1 | I36: 1 | J36: 0.9
B38: Region 4
A39: No. | B39: Item | C39: Kiegoi | D39: Michimikuru | E39: Githongo | F39: Imenti | G39: Kionyo | H39: Kinoro | I39: Igembe | J39: Weru
A40: 1 | B40: Chaipro Financials | C40: Ok 2.5.5.9 | D40: Ok 2.5.5.9 | E40: Ok 2.5.5.9 | F40: Ok 2.5.5.9 | G40: Ok 2.5.5.9 | H40: Ok 2.5.5.9 | I40: Ok 2.5.5.9 | J40: Ok 2.5.5.9
A41: 2 | B41: Chaipro Factory/ TVAP | C41: Ok 2.5.2.7 | D41: Ok 2.5.2.7 | E41: Ok 2.5.2.7 | F41: Ok 2.5.2.7 | G41: Ok 2.5.2.7 | H41: Ok 2.5.2.7 | I41: Ok 2.5.2.7 | J41: Ok 2.5.2.7
A42: 3 | B42: Chaipro Farmers | C42: Ok 3.0.0.1 | D42: Ok 3.0.0.1 | E42: Ok 3.0.0.1 | F42: Ok 3.0.0.1 | G42: Ok 3.0.0.1 | H42: Ok 3.0.0.1 | I42: Ok 3.0.0.1 | J42: Ok 3.0.0.1
A43: 4 | B43: Chaipro Fleet | C43: Ok 3.2.5.1 | D43: Ok 3.2.5.1 | E43: Ok 3.2.5.1 | F43: Ok 3.2.5.1 | G43: Ok 3.2.5.1 | H43: Ok 3.2.5.1 | I43: Ok 3.2.5.1 | J43: Ok 3.2.5.1
A44: 6 | B44: KTDA Replicator | C44: Ok 0.0.0.1 | D44: Ok 0.0.0.1 | E44: Ok 0.0.0.1 | F44: Ok 0.0.0.1 | G44: Ok 0.0.0.1 | H44: Ok 0.0.0.1 | I44: Ok 0.0.0.1 | J44: Ok 0.0.0.1
...

Sheet ICT Inventory
B1: Region 1 | J1: ='Infrastructure and Systems'!M2 -> 45930
A2: No. | B2: Item/Factory | C2: KAMBAA | D2: KAGWE | E2: THETA | F2: Ndarugu | G2: GACHEGE | H2: MATAARA | I2: NGERE | J2: NJUNU | K2: MAKOS | L2: NDUTI | M2: IKUMBI | N2: GACHARAGE
A3: 1 | B3: Network Equipment (e.g. Switches and routers functionality and any other additional information) | C3: Fully Operational | D3: Fully Operational | E3: Fully Operational | F3: Fully Operational | G3: Fully Operational | H3: Fully Operational | I3: Fully Operational | J3: Fully Operational | K3: Fully Operational | L3: Fully Operational | M3: Fully Operational | N3: Fully Operational
A4: 2 | B4: Software (e.g. 3rd party, Licenses, etc.) | C4: Procured 10 Licences for Microsoft 2016 | D4: Procured 5 Licences for Microsoft 2016 | E4: Procured 6 Licences for Microsoft 2016 | F4: Procured 5 Licences for Microsoft 2016 | G4: Procured 10 Licences for icrosoft 2016 | H4: EWS software, Windows server software, Office 2016. | I4: Procured 5 Licences for Microsoft 2016 | J4: Procured 5 Licences for microsoft 2016 | K4: Procured 10 Licenses for Microsoft 2016 in October | L4: Raised an order of 7 Microsoft 2016 office | M4: OPERATIONALIZED for MS office licenses | N4: Procured 7 Licences for Microsoft 2016
A5: 3 | B5: Hardware (e.g. Servers, | C5: Fully Operational | D5: Fully Operational | E5: Fully Operational | F5: Fully Operational | G5: Fully Operational | H5: Fully Operational | I5: Fully Operational | J5: Fully Operational | K5: Fully Operational | L5: Fully Operational | M5: Fully Operational | N5: Fully Operational
B6: PCs, | C6: Fully Operational | D6: Fully Operational | E6: Fully Operational | F6: Fully Operational | G6: Fully Operational | H6: Fully Operational | I6: Fully Operational | J6: Fully Operational | K6: Fully Operational | L6: Fully Operational | M6: Fully Operational | N6: Fully Operational
B7: Laptops, | C7: Fully Operational | D7: Fully Operational | E7: Fully Operational | F7: Fully Operational | G7: Fully Operational | H7: Fully Operational | I7: Fully Operational | J7: Fully Operational | K7: Fully Operational | L7: Fully Operational | M7: Fully Operational | N7: Fully Operational
B8: UPS's | C8: Fully Operational | D8: Fully Operational | E8: Fully Operational | F8: Fully Operational | G8: Fully Operational | H8: Fully Operational | I8: Fully Operational | J8: Fully Operational | K8: Fully Operational | L8: Fully Operational | M8: Fully Operational | N8: Fully Operational
B9: Das, | C9: Fully Operational | D9: Fully Operational | E9: Fully Operational | F9: Fully Operational | G9: Fully Operational | H9: Fully Operational | I9: Fully Operational | J9: Fully Operational | K9: Fully Operational | L9: Fully Operational | M9: Fully Operational | N9: Fully Operational
B10: Printers, | C10: Fully Operational | D10: Fully Operational | E10: Fully Operational | F10: Fully Operational | G10: Fully Operational | H10: Fully Operational | I10: Fully Operational | J10: Fully Operational | K10: Fully Operational | L10: Fully Operational | M10: Fully Operational | N10: Fully Operational
B11: Scanners, | C11: Fully Operational | D11: Fully Operational | E11: Fully Operational | F11: Fully Operational | G11: Fully Operational | H11: Fully Operational | I11: Fully Operational | J11: Fully Operational | K11: Fully Operational | L11: Fully Operational | M11: Fully Operational | N11: Fully Operational
B12: ESD, | C12: Fully Operational | D12: Fully Operational | E12: Fully Operational | F12: Fully Operational | G12: Fully Operational | H12: Fully Operational | I12: Fully Operational | J12: Fully Operational | K12: Fully Operational | L12: Fully Operational | M12: Fully Operational | N12: Fully Operational
B13: Fiscal Printers) | C13: Fully Operational | D13: Fully Operational | E13: Fully Operational | F13: Fully Operational | G13: Fully Operational | H13: Fully Operational | I13: Fully Operational | J13: Fully Operational | K13: Fully Operational | L13: Fully Operational | M13: Fully Operational | N13: Fully Operational
A14: 4 | B14: Firewall | C14: Sophos License Expired | D14: Sophos License Expired | E14: Sophos License Valid | F14: Sophos License Valid | G14: Sophos License Expired | H14: Sophos License Expired | I14: Sophos License Expired | J14: Sophos License Expired | K14: Sophos License Expired | L14: Sophos License Expired | M14: Sophos License Expired | N14: Sophos License Expired
A15: 5 | B15: Tablets | C15: Fully Operational | D15: Fully Operational | E15: Fully Operational | F15: Fully Operational | G15: Fully Operational | H15: Fully Operational | I15: Fully Operational | J15: Fully Operational | K15: Fully Operational | L15: Fully Operational | M15: Fully Operational | N15: Fully Operational
A16: 6 | B16: EWS (Working)
B17: PDA | C17: 10 | D17: 9 | E17: 7 | F17: 8 | G17: 8 | H17: 8 | J17: 7 | K17: 14 | L17: 7 | M17: 10 | N17: 8
B18: SCALE | C18: 10 | D18: 9 | E18: 7 | F18: 8 | G18: 8 | H18: 8 | J18: 7 | K18: 14 | L18: 7 | M18: 10 | N18: 8
B19: PRINTER | C19: 10 | D19: 9 | E19: 7 | F19: 8 | G19: 8 | H19: 8 | J19: 7 | K19: 14 | L19: 7 | M19: 10 | N19: 8
A20: 7 | B20: Other Equipment (please specify) | C20: none | D20: none | E20: none | F20: none | G20: none | H20: none | I20: none | J20: none | K20: none | L20: none | M20: none | N20: none
B22: Region 2 | J22: ='Infrastructure and Systems'!M23 -> 0
A23: No. | B23: Item/Factory | C23: Ragati | D23: Gathuthi | E23: Gitugi | F23: Iriaini | G23: Chinga | H23: Kiru | I23: Gatunguru | J23: Kanyenyaini | K23: Githambo
A24: 1 | B24: Network Equipment (e.g. Switches and routers functionality and any other additional information) | C24: functional | D24: functional | E24: functional | F24: functional | G24: functional | H24: functional | I24: functional | J24: functional | K24: functional
A25: 2 | B25: Software (e.g. 3rd party, Licenses, etc.) | C25: functional | D25: functional | E25: functional | F25: functional | G25: functional | H25: functional | I25: functional | J25: functional | K25: functional
A26: 3 | B26: Hardware (e.g. Servers, | C26: functional | D26: functional | E26: functional | F26: functional | G26: functional | H26: functional | I26: functional | J26: functional | K26: functional
B27: PCs, | C27: functional | D27: functional | E27: functional | F27: functional | G27: functional | H27: functional | I27: functional | J27: functional | K27: functional
B28: Laptops, | C28: functional | D28: functional | E28: functional | F28: functional | G28: functional | H28: functional | I28: functional | J28: functional | K28: functional
B29: UPS's | C29: functional | D29: functional | E29: functional | F29: functional | G29: functional | H29: functional | I29: functional | J29: functional | K29: functional
B30: Das, | C30: functional | D30: functional | E30: functional | F30: functional | G30: functional | H30: functional | I30: functional | J30: functional | K30: functional
B31: Printers, | C31: functional | D31: functional | E31: functional | F31: functional | G31: functional | H31: functional | I31: functional | J31: functional | K31: functional
B32: Scanners, | C32: functional | D32: functional | E32: functional | F32: functional | G32: functional | H32: functional | I32: functional | J32: functional | K32: functional
B33: ESD, | C33: functional | D33: functional | E33: functional | F33: functional | G33: functional | H33: functional | I33: functional | J33: functional | K33: functional
B34: Fiscal Printers) | C34: functional | D34: functional | E34: functional | F34: functional | G34: functional | H34: functional | I34: functional | J34: functional | K34: functional
A35: 4 | B35: Firewall | C35: functional | D35: functional | E35: functional | F35: functional | G35: functional | H35: functional | I35: functional | J35: functional | K35: functional
A36: 5 | B36: Tablets
A37: 6 | B37: EWS (Working)
B38: PDA
B39: SCALE
B40: PRINTER
A41: 7 | B41: Other Equipment (please specify)
...

Sheet BCP
B1: Region 1 | F1: ='Infrastructure and Systems'!M2 -> 45930
A2: No. | B2: Item/Factory | C2: KAMBAA | D2: KAGWE | E2: THETA | F2: NDARUGU | G2: GACHEGE | H2: MATAARA | I2: NGERE | J2: NJUNU | K2: MAKOS | L2: NDUTI | M2: IKUMBI | N2: GACHEGE
A3: 1 | B3: Onsite Backup | C3: In place | D3: In place | E3: In place | F3: In place | G3: In place | H3: In place | I3: In place | J3: In place | K3: In place | L3: In place | M3: In place | N3: In place
A4: 2 | B4: Remote Backup | C4: In place | D4: In place | E4: In place | F4: In place | G4: In place | H4: In place | I4: In place | J4: In place | K4: In place | L4: In place | M4: In place | N4: In place
A5: 3 | B5: Mail Server Backup (Date) | C5: 45931 | D5: 45931 | E5: 45931 | F5: 45931 | G5: 45931 | H5: 45931 | I5: 45931 | J5: 45931 | K5: 45931 | L5: 45931 | M5: 45931 | N5: 45931
B7: Region 2
A8: No. | B8: Item/Factory | C8: Ragati | D8: Gathuthi | E8: Gitugi | F8: Iriaini | G8: Chinga | H8: Kiru | I8: Gatunguru | J8: Kanyenyaini
A9: 1 | B9: Onsite Backup | C9: SQL chaipro backup EWS 2 Backup | D9: SQL chaipro backup EWS 2 Backup | E9: SQL chaipro backup EWS 2 Backup | F9: SQL chaipro backup EWS 2 Backup | G9: SQL chaipro backup EWS 2 Backup | H9: SQL chaipro backup EWS 2 Backup | I9: SQL chaipro backup EWS 2 Backup | J9: SQL chaipro backup EWS 2 Backup
A10: 2 | B10: Remote Backup | C10: SQL chaipro backup EWS 2 Backup | D10: SQL chaipro backup EWS 2 Backup | E10: SQL chaipro backup EWS 2 Backup | F10: SQL chaipro backup EWS 2 Backup | G10: SQL chaipro backup EWS 2 Backup | H10: SQL chaipro backup EWS 2 Backup | I10: SQL chaipro backup EWS 2 Backup | J10: SQL chaipro backup EWS 2 Backup
A11: 3 | B11: Mail Server Backup (Date)
B13: Region 3
A14: No. | B14: Item/Factory | C14: NDIMA | D14: MUNUNGA | E14: KANGAITA | F14: KIMUNYE | G14: THUMAITA | H14: KATHANGARIRI | I14: MUNGANIA | J14: RUKURIRI
A15: 1 | B15: Onsite Backup | C15: Automated Full Back up on external hard drive | D15: Weighbridge PC | E15: Done at the weighbridge pc | F15: Ok | G15: In place | H15: Okay | I15: Ok | J15: Ok
A16: 2 | B16: Remote Backup | C16: Region office 4:00am | D16: Region office 4:00am | E16: Regional office 10:50 pm | F16: Regional office 2:50 pm | G16: In place | H16: Okay | I16: Regional office 11:55 pm | J16: Regional office 10:05 pm
A17: 3 | B17: Mail Server Backup (Date) | D17: 45904 | E17: [3.10.2025] | F17: Ok | G17: [03.10.2025] | H17: [03.10.2025] | I17: [03.10.2025]
B20: Region 4
A21: No. | B21: Item/Factory | C21: Kiegoi | D21: Michimikuru | E21: Githongo | F21: Imenti | G21: Kionyo | H21: Kinoro | I21: Igembe | J21: Weru
A22: 1 | B22: Onsite Backup | C22: Back to PC machine Back up to External HDD | D22: Back to A PC machine Back up to External HDD | E22: Back to PC machine Back up to External HDD | F22: Back to PCmachine Back up to External HDD | G22: Back to PC machine Back up to External HDD | H22: Back to PC machine Back up to External HDD | I22: Back to PC machine Back up to External HDD | J22: Back to PC machine Back up to External HDD
A23: 2 | B23: Remote Backup | C23: Not yet active | D23: Not yet active | E23: Not yet active | F23: Not yet active | G23: Not yet active | H23: Not yet active | I23: Not yet active | J23: Not yet active
A24: 3 | B24: Mail Server Backup (Date) | C24: Back up done on 30/9 | D24: Back up done on 30/9 | E24: Back up done on 30/9 | F24: Back up done on 30/9 | G24: Back up done on 30/9 | H24: Back up done on 30/9 | I24: Back up done on 30/9 | J24: Back up done on 30/9
B26: Region 5
A27: No. | B27: Item | C27: KAPKATET | D27: MOMUL | E27: TEGAT | F27: CHELAL | G27: TEBESONIK | H27: LITEIN | I27: TOROR | J27: KAPSET | K27: MOGOGSIEK | L27: MOTIGO | M27: KOBEL | N27: KAPKOROS | O27: TRIGAGA | P27: ROROK | Q27: OLENGRUONE | R27: BOITO | S27: MOTIGO | T27: KOBEL | U27: KAPKOROS | V27: TRIGAGA | W27: ROROK | X27: OLENGRUONE | Y27: BOITO
A28: 1 | B28: Onsite Backup | C28: In Place | D28: OK | E28: Ok/tested | F28: working | G28: In Place | H28: working | I28: Ok/tested | J28: local backup 10.11.6.31 | K28: ok | L28: OK | M28: OK | N28: Working | O28: OK | P28: local backup 10.11.16.150 | Q28: OK | S28: OK | T28: OK | U28: Working | V28: OK | W28: local backup 10.11.16.150 | X28: OK
A29: 2 | B29: Remote Backup | C29: External HDD | D29: N/A | E29: No remote backup | F29: working | H29: working | I29: No remote backup | J29: Remote 10.11.16.150 | K29: non | L29: N/A | M29: N/A | N29: N/A | O29: OK | P29: Remote 10.11.6.31 | Q29: Not Available. | S29: N/A | T29: N/A | U29: N/A | V29: OK | W29: Remote 10.11.6.31 | X29: Not Available.
A30: 3 | B30: Mail Server Backup (Date) | C30: 25.09.2025 | E30: Ok/30/09/2025 | G30: 30.09.2025 | I30: Ok/30/09/2025 | J30: None in place | K30: 25th Sep 2025 | P30: None in place | Q30: 3rd Oct 2025 | W30: None in place | X30: 3rd Oct 2025
B32: Region 6
A33: No. | B33: Item/Factory | C33: Gianchore | D33: Sanganyi | E33: Kebirigo | F33: Tombe | G33: Matunwa | H33: Nyansiongo | I33: Nyankoba | J33: Sombogo | K33: Kiamokama | L33: Mwamu | M33: Nyamache | N33: Itumbe | O33: Ogembo | P33: Eberege
A34: 1 | B34: Onsite Backup | C34: Automated Full Back up on external hard drive | D34: Weighbridge PC | E34: Done at the weighbridge pc | F34: Ok | G34: In place | H34: Okay | I34: Ok | J34: Ok | K34: Ok | L34: Ok | M34: Ok | N34: Full back up on One remote computer | O34: Weighbridge PC | P34: Weighbridge/GL Clerk PC
A35: 2 | B35: Remote Backup | C35: Region office 4:00am | D35: Region office 4:00am | E35: Regional office 10:50 pm | F35: Regional office 2:50 pm | G35: In place | H35: Okay | I35: Regional office 11:55 pm | J35: Regional office 10:05 pm | K35: Regional office 11:00 pm | L35: Regional office 10:20 pm | M35: Regional office 11:00am | N35: automatically every night to an external hard disk and region office 12:00 am. | O35: Region office 12:05 am | P35: Region office 3:00 pm
A36: 3 | B36: Mail Server Backup (Date) | D36: 45904 | E36: [3.10.2025] | F36: Ok | G36: [03.10.2025] | H36: [03.10.2025] | I36: [03.10.2025] | K36: [02/10/2025] | M36: [5TH OCT 2025] | N36: [11th September 2025] | O36: 45930 | P36: 45904
B38: Region 7
A39: No. | B39: Item/Factory | C39: Chebut | D39: Kaptumo | E39: Mudete | F39: Kapsara
A40: 1 | B40: Onsite Backup | C40: Okay | D40: Okay | E40: Okay | F40: Okay
A41: 2 | B41: Remote Backup | C41: Okay | D41: Not Working | E41: Not Working | F41: Not Working
A42: 3 | B42: Mail Server Backup (Date) | C42: 02.10.2025

Sheet ICT Cost
A1: Region 1 | K1: ='Infrastructure and Systems'!M2 -> 45930
A2: Item | B2: Kambaa | C2: Kagwe | D2: Theta | E2: Gachege | F2: Ndarugu | G2: Mataara | H2: Ngere | I2: Gacharage | J2: Ikumbi | K2: Nduti | L2: Makos | M2: Njunu | N2: Total
A3: Recurrent costs for the month | B3: 168896.79 | C3: 181420 | D3: 116487.47 | E3: 24000.75 | F3: 26783 | G3: 70121.37 | H3: 507991.43 | I3: 92217.6 | J3: 168896.79 | K3: 25100 | L3: 62309.6 | M3: 63741.26 | N3: =SUM(B3:M3) -> 1507966.1
A4: Capital costs for the month | B4: 0 | C4: - | D4: 396253.8 | E4: 0 | F4: 0 | G4: - | H4: 0 | I4: 0 | J4: 0 | K4: 889000 | L4: 0 | M4: 0 | N4: =SUM(B4:M4) -> 1285253.8
A5: Total Cost for month | B5: 168896.79 | C5: 181420 | D5: 512741.27 | E5: 24000.75 | F5: 26783 | G5: 70121.37 | H5: 507991.43 | I5: 92217.6 | J5: 168896.79 | K5: 914100 | L5: 62309.6 | M5: 63741.26 | N5: =SUM(B5:M5) -> 2793219.9
A6: Recurrent to date as at AUG 25 | B6: 465516.79 | C6: 538470 | D6: 175977.09 | E6: 234062.5 | F6: 370125 | G6: 292859.37 | H6: 1084650.4 | I6: 175635.24 | J6: 223971.79 | K6: 249158 | L6: 169619.6 | M6: 348741.26 | N6: =SUM(B6:M6) -> 4328787.1
A7: Capital to date as at AUG 25 | D7: 396253.8 | E7: 1331680 | K7: 889000 | N7: =SUM(B7:M7) -> 2616933.8
A8: Total Cost As at AUG FOR ICT Fin. Yr 25.26 | B8: 465516.79 | C8: 538470 | D8: 572230.89 | E8: 1565742.5 | F8: 370125 | G8: 292859.37 | H8: 1084650.4 | I8: 175635.24 | J8: 223971.79 | K8: 1138158 | L8: 169619.6 | M8: 348741.26 | N8: =SUM(B8:M8) -> 6945720.9
A9: Comments
A10: BUDGET 25.26 | N10: =SUM(B10:M10) -> 0
A12: Region 2
A13: Item/Factory | B13: Ragati | C13: Gathuthi | D13: Gitugi | E13: Iriaini | F13: Chinga | G13: Kiru | H13: Gatunguru | I13: Kanyenyaini | J13: Githambo | K13: TOTALS
A14: Recurrent costs (month) | B14: 16700 | C14: 0 | D14: 0 | E14: 0 | F14: 0 | G14: 18,100 | H14: 110000 | I14: 0 | J14: 66368 | K14: =SUM(B14:J14) -> 193068
A15: Capital costs (month) | B15: 0 | C15: 0 | D15: 0 | E15: 0 | F15: 0 | G15: 0 | H15: 0 | I15: 218,080 | J15: 48,000 | K15: =SUM(B15:J15) -> 0
A16: Total Cost (month) | B16: 16700 | C16: 0 | D16: 0 | E16: 0 | F16: 0 | G16: 50168 | H16: 110000 | I16: 0 | J16: 114368 | K16: =SUM(B16:J16) -> 291236
A17: Recurrent (To Date) | B17: 43900 | C17: 0 | D17: 39560 | E17: 6420 | F17: 27168 | G17: 50168 | H17: 260,000 | I17: 0 | J17: 183,816 | K17: =SUM(B17:J17) -> 94068
A18: Capital Costs (To Date) | B18: 0 | C18: 0 | D18: 0 | E18: 0 | F18: 0 | G18: 0 | H18: 0 | I18: 0 | J18: 415,810 | K18: =SUM(B18:J18) -> 0
A19: Total Cost to date (2025/2026) | B19: 43900 | C19: 0 | D19: 39560 | E19: 6420 | F19: 27168 | G19: 50,168 | H19: 260,000 | I19: 218,080 | J19: 599626 | K19: =SUM(B19:J19) -> 643526
A20: Comments
A21: Total Budget (2025/2026)
A24: Region 3
A25: Item | B25: NDIMA | C25: MUNUNGA | D25: KANGAITA | E25: KIMUNYE | F25: THUMAITA | G25: KATHANGARIRI | H25: MUNGANIA | I25: RUKURIRI | J25: TOTALS
A26: Recurrent costs for the month | B26: 64500 | C26: 52600 | D26: 76800 | E26: 86000 | F26: 111749.93 | G26: 57866.6 | H26: 26800 | I26: 101335.54 | J26: =SUM(B26:I26) -> 577652.07
A27: Capital costs for the month | B27: 0 | C27: 0 | D27: 2,8,000,000.00 | E27: 0 | F27: 0 | H27: 0 | I27: 0 | J27: =SUM(B27:I27) -> 0
A28: Total Cost for month | J28: =SUM(B28:I28) -> 0
A29: Recurrent to date | B29: 630000 | C29: 528000 | D29: 245500 | E29: 230660 | F29: 411592.65 | G29: 639425.77 | H29: 477.900.00 | I29: 261132.2 | J29: =SUM(B29:I29) -> 2946310.6
A30: Capital to date | D30: 2,8,000,000.00 | J30: =SUM(B30:I30) -> 0
A31: Total Cost to date 2023/2024 | J31: =SUM(B31:I31) -> 0
A32: Comments
A33: Total Budget 2024/2025 | B33: 23500000 | C33: 15000000 | D33: 13500000 | E33: 24718302 | F33: 15830000 | G33: 13500000 | H33: 15531411 | I33: 32275600 | J33: =SUM(B33:I33) -> 153855313
A35: Region 4
A36: Item/Factory | B36: Weru | C36: Kinoro | D36: Kionyo | E36: Imenti | F36: Githongo | G36: Michi | H36: Kiegoi | I36: Igembe | J36: TOTALS
A37: Recurrent costs (month) | B37: 57500 | C37: 0 | D37: 55595 | E37: 78000 | F37: 58250 | G37: 0 | H37: 62946.6 | I37: 45002 | J37: =SUM(B37:I37) -> 357293.6
A38: Capital costs (month) | B38: 0 | C38: 0 | D38: 184699 | E38: 0 | F38: 0 | G38: 0 | H38: 0 | I38: 0 | J38: =SUM(B38:I38) -> 184699
A39: Total Cost (month) | B39: 57500 | C39: 0 | D39: 240294 | E39: 78000 | F39: 58250 | G39: 0 | H39: 62946.6 | I39: 45002 | J39: =SUM(B39:I39) -> 541992.6
A40: Recurrent (To Date) | B40: 160053.89 | C40: 0 | D40: 322365.75 | E40: 156000 | F40: 133350 | G40: 225220 | H40: 142387.1 | I40: 111267.23 | J40: =SUM(B40:I40) -> 1250644
A41: Capital Costs (To Date) | B41: 0 | C41: 0 | D41: 774899 | E41: 0 | F41: 0 | G41: 0 | H41: 0 | I41: 0 | J41: =SUM(B41:I41) -> 774899
A42: Total Cost to date (2025/2026) | B42: 160053.89 | C42: 0 | D42: 1097264.8 | E42: 234000 | F42: 133350 | G42: 225220 | H42: 142387.1 | I42: 111267.23 | J42: =SUM(B42:I42) -> 2103543
A43: Comments | H43: No capital items purchased yet. | I43: No capital items purchased yet. | J43: =SUM(B43:I43) -> 0
A44: Total Budget (2025/2026) | C44: 15000000 | D44: 16679960 | E44: 15512000 | F44: 6000000 | G44: 13870000 | H44: 21680000 | I44: 21680000 | J44: =SUM(C44:I44) -> 110421960
...

Sheet R1
B1: Region 1 | G1: 45838
B2: Infrastructure
A3: ='Infrastructure and Systems'!A3 -> No. | B3: Service | C3: No of Factories | D3: Region 1 | E3: % Uptime Service | F3: Factories Having Issues | G3: Summary of Issues | H3: Duration (days) | I3: Tickets Raised
A4: ='Infrastructure and Systems'!A4 -> 1 | B4: ='Infrastructure and Systems'!B4 -> Local Area Network (LAN) | C4: =COUNTA('Infrastructure and Systems'!$C$3:$N$3) -> 12 | D4: =COUNTIF('Infrastructure and Systems'!C4:N4,"No Issue Reported")+COUNTIF('Infrastructure and Systems'!C4:N4,"Partially Working")*0.7+COUNTIF('Infrastructure and Systems'!C4:N4,"Total Failure")*0.3 -> 0 | E4: =D4/C4 -> 0
A5: ='Infrastructure and Systems'!A5 -> 2 | B5: ='Infrastructure and Systems'!B5 -> Wide Area Network (WAN) | C5: =COUNTA('Infrastructure and Systems'!$C$3:$N$3) -> 12 | D5: =COUNTIF('Infrastructure and Systems'!C5:N5,"No Issue Reported")+COUNTIF('Infrastructure and Systems'!C5:N5,"Partially Working")*0.7+COUNTIF('Infrastructure and Systems'!C5:N5,"Total Failure")*0.3 -> 0 | E5: =D5/C5 -> 0
A6: ='Infrastructure and Systems'!A7 -> 4 | B6: ='Infrastructure and Systems'!B7 -> Firewall | C6: =COUNTA('Infrastructure and Systems'!$C$3:$N$3) -> 12 | D6: =COUNTIF('Infrastructure and Systems'!C7:N7,"No Issue Reported")*1+COUNTIF('Infrastructure and Systems'!C7:N7,"Partially Working")*0.7+COUNTIF('Infrastructure and Systems'!C7:N7,"Total Failure")*0.3 -> 0 | E6: =IF('Infrastructure and Systems'!C7="Internet slow even sometimes not available",(D6/C6),(D6/C6)) -> 0
A7: ='Infrastructure and Systems'!A8 -> 5 | B7: ='Infrastructure and Systems'!B8 -> E-Mail Server | C7: =COUNTA('Infrastructure and Systems'!$C$3:$N$3) -> 12 | D7: =COUNTIF('Infrastructure and Systems'!C8:N8,"Domino in use")*1+COUNTIF('Infrastructure and Systems'!C8:N8,"Exchange in Use")*0.8+COUNTIF('Infrastructure and Systems'!C8:N8,"Domino In Use-Issues")*0.6+COUNTIF('Infrastructure and Systems'!C8:N8,"Exchange In Use-Issues")*0.4+COUNTIF('Infrastructure and Systems'!C8:N8,"None")*0.2 -> 0 | E7: =D7/C7 -> 0
A8: ='Infrastructure and Systems'!A9 -> 6 | B8: ='Infrastructure and Systems'!B9 -> Business Servers (EWS, Chaipro) | C8: =COUNTA('Infrastructure and Systems'!$C$3:$N$3) -> 12 | D8: =COUNTIF('Infrastructure and Systems'!C9:N9,"No Issue Reported")+COUNTIF('Infrastructure and Systems'!C9:N9,"Partially Working")*0.7+COUNTIF('Infrastructure and Systems'!C9:N9,"Total Failure")*0.3 -> 0 | E8: =D8/C8 -> 0
A9: ='Infrastructure and Systems'!A10 -> 7 | B9: ='Infrastructure and Systems'!B10 -> Electronic Weighment Solution (EWS Version) | C9: =COUNTA('Infrastructure and Systems'!$C$3:$N$3) -> 12 | D9: =COUNTIF('Infrastructure and Systems'!C10:N10,"No Issue Reported")+COUNTIF('Infrastructure and Systems'!C10:N10,"Partially Working")*0.7+COUNTIF('Infrastructure and Systems'!C10:N10,"Total Failure")*0.3 -> 0 | E9: =D9/C9 -> 0
A10: ='Infrastructure and Systems'!#REF! -> #REF! | B10: ='Infrastructure and Systems'!#REF! -> #REF! | C10: =COUNTA('Infrastructure and Systems'!$C$3:$N$3) -> 12 | D10: =COUNTIF('Infrastructure and Systems'!#REF!,"No Issue Reported")+COUNTIF('Infrastructure and Systems'!#REF!,"Partially Working")*0.7+COUNTIF('Infrastructure and Systems'!#REF!,"Total Failure")*0.3 -> #REF! | E10: =D10/C10 -> #REF!
B11: Average | E11: =AVERAGE(E4:E10) -> #REF!
B13: ChaiPro/SAP
A14: No | B14: Service | C14: No of Factories | D14: Region 1 | E14: % Uptime Service | F14: Factories Affected | G14: Issue
A15: 1 | B15: Chaipro Financials | C15: =COUNTA('Chaipro-SAP'!$C$3:$N$3) -> 12 | D15: =COUNTIF('Chaipro-SAP'!C3:N3,"SAP Module-FICO/MM")*1+COUNTIF('Chaipro-SAP'!C3:N3,"2.5.5.7")*1+COUNTIF('Chaipro-SAP'!C3:N3,"2.5.5.8")*1+COUNTIF('Chaipro-SAP'!C3:N3,"2.5.5.9")*1+COUNTIF('Chaipro-SAP'!C3:N3,"Other version Working")*0.8+COUNTIF('Chaipro-SAP'!C3:N3,"2.5.5.7 With Issues")*0.6+COUNTIF('Chaipro-SAP'!C3:N3,"Other version With Issues")*0.4 + COUNTIF('Chaipro-SAP'!C3:N3,"None")*0.25 -> 12 | E15: =D15/C15 -> 1
A16: 2 | B16: Chaipro Factory/TVAP | C16: =COUNTA('Chaipro-SAP'!$C$3:$N$3) -> 12 | D16: =COUNTIF('Chaipro-SAP'!C4:N4,"SAP Module-PP/PM")*1+COUNTIF('Chaipro-SAP'!C4:N4,"2.5.2.5")*1+COUNTIF('Chaipro-SAP'!C4:N4,"2.5.2.7")*1+COUNTIF('Chaipro-SAP'!C4:N4,"Other version Working")*0.8+COUNTIF('Chaipro-SAP'!C4:N4,"2.5.2.5 With Issues")*0.6+COUNTIF('Chaipro-SAP'!C4:N4,"Other version With Issues")*0.4 + COUNTIF('Chaipro-SAP'!C4:N4,"None")*0.25 -> 12 | E16: =D16/C16 -> 1
A17: 3 | B17: Chaipro Farmers | C17: =COUNTA('Chaipro-SAP'!$C$3:$N$3) -> 12 | D17: =COUNTIF('Chaipro-SAP'!C5:N5,"2.8.0.0")*1+COUNTIF('Chaipro-SAP'!C5:N5,"Other version Working")*0.8+COUNTIF('Chaipro-SAP'!C5:N5,"2.8.0.0 With Issues")*0.6+COUNTIF('Chaipro-SAP'!C5:N5,"Other version With Issues")*0.4 + COUNTIF('Chaipro-SAP'!C5:N5,"None")*0.25 -> 12 | E17: =D17/C17 -> 1
A18: 4 | B18: Chaipro Fleet | C18: =COUNTA('Chaipro-SAP'!$C$3:$N$3) -> 12 | D18: =COUNTIF('Chaipro-SAP'!C6:N6,"3.2.5.1")*1+COUNTIF('Chaipro-SAP'!C6:N6,"Other version Working")*0.8+COUNTIF('Chaipro-SAP'!C6:N6,"3.2.5.1 With Issues")*0.6+COUNTIF('Chaipro-SAP'!C6:N6,"Other version With Issues")*0.4 + COUNTIF('Chaipro-SAP'!C6:N6,"None")*0.25 -> 12 | E18: =D18/C18 -> 1
A19: 6 | B19: KTDA Replicator | C19: =COUNTA('Chaipro-SAP'!$C$3:$N$3) -> 12 | D19: =COUNTIF('Chaipro-SAP'!C7:N7,"Working")*1+COUNTIF('Chaipro-SAP'!C7:N7,"Version 10 fully operational ")*1+COUNTIF('Chaipro-SAP'!C7:N7,"Working With Issues")*0.5 -> 12 | E19: =D19/C19 -> 1
A20: 7 | B20: Chai Data | C20: =COUNTA('Chaipro-SAP'!$C$3:$N$3) -> 12 | D20: =COUNTIF('Chaipro-SAP'!C8:N8,"1.0.0.3")*1+COUNTIF('Chaipro-SAP'!C8:N8,"Other version Working")*0.8+COUNTIF('Chaipro-SAP'!C8:N8,"1.0.0.3 With Issues")*0.6+COUNTIF('Chaipro-SAP'!C8:N8,"Other version With Issues")*0.4 + COUNTIF('Chaipro-SAP'!C8:N8,"None")*0.25 -> 12 | E20: =D20/C20 -> 1
A21: 8 | B21: Chai POS | C21: =COUNTA('Chaipro-SAP'!$C$3:$N$3) -> 12 | D21: =COUNTIF('Chaipro-SAP'!C9:N9,"2.2")*1+COUNTIF('Chaipro-SAP'!C9:N9,"Other version Working")*0.8+COUNTIF('Chaipro-SAP'!C9:N9,"2.2 With Issues")*0.6+COUNTIF('Chaipro-SAP'!C9:N9,"Other version With Issues")*0.4 + COUNTIF('Chaipro-SAP'!C9:N9,"None")*0.25 -> 0 | E21: =D21/C21 -> 0
B22: Average | E22: =AVERAGE(E15:E21) -> 0.85714286
B24: Inventory
A25: No | B25: Service | C25: No of Factories | D25: Region 1 | E25: % Uptime Service | F25: Factories Affected | G25: Issue
A26: 1 | B26: Network Equipments (e.g. Switch, 2, Functional, any additional details) | C26: =COUNTA('ICT Inventory'!#REF!) -> 1 | D26: =COUNTIF('ICT Inventory'!#REF!,"No Issue Reported")+COUNTIF('ICT Inventory'!#REF!,"Partially Working")*0.7+COUNTIF('ICT Inventory'!#REF!,"Total Failure")*0.3 -> #REF! | E26: =D26/C26 -> #REF!
A27: 2 | B27: Software (e.g. third party software) etc | C27: =COUNTA('ICT Inventory'!#REF!) -> 1 | D27: =COUNTIF('ICT Inventory'!#REF!,"No Issue Reported")+COUNTIF('ICT Inventory'!#REF!,"Partially Working")*0.7+COUNTIF('ICT Inventory'!#REF!,"Total Failure")*0.3 -> #REF! | E27: =D27/C27 -> #REF!
A28: 3 | B28: Hardware (e.g. Servers, PCs, Laptops, UPS, DAs, Printers, Scanners, ESD, Fiscal Printers, Tablets) | C28: =COUNTA('ICT Inventory'!#REF!) -> 1 | D28: =COUNTIF('ICT Inventory'!#REF!,"No Issue Reported")+COUNTIF('ICT Inventory'!#REF!,"Partially Working")*0.7+COUNTIF('ICT Inventory'!#REF!,"Total Failure")*0.3 -> #REF! | E28: =D28/C28 -> #REF!
A29: 4 | B29: Other Equipment (please specify) | C29: =IF('ICT Inventory'!#REF!<>"N/A",COUNTA('ICT Inventory'!#REF!)) -> #REF! | D29: =COUNTIF('ICT Inventory'!#REF!,"No Issue Reported")*1+COUNTIF('ICT Inventory'!#REF!,"WIFI & CCTV Installed")*1+COUNTIF('ICT Inventory'!#REF!,"Partially Working")*0.7+COUNTIF('ICT Inventory'!#REF!,"Total Failure")*0.3 -> #REF! | E29: =D29/C29 -> #REF!
B30: Average | E30: =AVERAGE(E26:E29) -> #REF!
B32: BCP
A33: No | B33: Service | C33: No of Factories | D33: Region 1 | E33: % Uptime Service | F33: Factories Affected | G33: Issue
A34: 1 | B34: Business Continuity Mechanism e.g. Backups | C34: =IF(BCP!#REF!<>"N/A",COUNTA(BCP!#REF!)) -> #REF! | D34: =COUNTIF(BCP!#REF!,"Offsite & Schedule backups in place") -> #REF! | E34: =D34/C34 -> #REF!
B35: Average | E35: =AVERAGE(E34) -> #REF!
B38: PURCHASES
A39: No | B39: Service | C39: No of Factories | D39: Total Cost | E39: Total Budget | F39: Factories Affected | G39: Issue
A40: 1 | B40: Purchases | C40: =COUNTA('ICT Cost'!$B$2:$L$2) -> 11 | D40: ='ICT Cost'!N8 -> 6945720.9
B41: Average

Sheet R2
B1: Region 2 | F1: 45838
B2: Infrastructure
A3: ='Infrastructure and Systems'!A3 -> No. | B3: Service | C3: No of Factories | D3: Region 2 | E3: % Uptime Service | F3: Factories Having Issues | G3: Summary of Issues | H3: Duration (days) | I3: Tickets Raised
A4: ='Infrastructure and Systems'!A4 -> 1 | B4: ='Infrastructure and Systems'!B4 -> Local Area Network (LAN) | C4: =COUNTA('Infrastructure and Systems'!$C$20:$K$20) -> 9 | D4: =COUNTIF('Infrastructure and Systems'!C21:K21,"No Issue Reported")+COUNTIF('Infrastructure and Systems'!C21:K21,"Partially Working")*0.7+COUNTIF('Infrastructure and Systems'!C21:K21,"Total Failure")*0.3 -> 9 | E4: =D4/C4 -> 1
A5: ='Infrastructure and Systems'!A5 -> 2 | B5: ='Infrastructure and Systems'!B5 -> Wide Area Network (WAN) | C5: =COUNTA('Infrastructure and Systems'!$C$20:$K$20) -> 9 | D5: =COUNTIF('Infrastructure and Systems'!C22:K22,"No Issue Reported")+COUNTIF('Infrastructure and Systems'!C22:K22,"Partially Working")*0.7+COUNTIF('Infrastructure and Systems'!C22:K22,"Total Failure")*0.3 -> 9 | E5: =D5/C5 -> 1
A6: ='Infrastructure and Systems'!A7 -> 4 | B6: ='Infrastructure and Systems'!B7 -> Firewall | C6: =COUNTA('Infrastructure and Systems'!$C$20:$K$20) -> 9 | D6: =COUNTIF('Infrastructure and Systems'!C23:K23,"No Issue Reported")+COUNTIF('Infrastructure and Systems'!C23:K23,"Partially Working")*0.7+COUNTIF('Infrastructure and Systems'!C23:K23,"Total Failure")*0.3 -> 9 | E6: =IF('Infrastructure and Systems'!C7="Internet slow even sometimes not available",(D6/C6)/2,(D6/C6)) -> 1
A7: ='Infrastructure and Systems'!A8 -> 5 | B7: ='Infrastructure and Systems'!B8 -> E-Mail Server | C7: =COUNTA('Infrastructure and Systems'!$C$20:$K$20) -> 9 | D7: =COUNTIF('Infrastructure and Systems'!C24:K24,"Domino in use")*1+COUNTIF('Infrastructure and Systems'!C24:K24,"Exchange in Use")*0.8+COUNTIF('Infrastructure and Systems'!C24:K24,"Domino In Use-Issues")*0.6+COUNTIF('Infrastructure and Systems'!C24:K24,"Exchange In Use-Issues")*0.4+COUNTIF('Infrastructure and Systems'!C24:K24,"None")*0.2 -> 9 | E7: =D7/C7 -> 1
A8: ='Infrastructure and Systems'!A9 -> 6 | B8: ='Infrastructure and Systems'!B9 -> Business Servers (EWS, Chaipro) | C8: =COUNTA('Infrastructure and Systems'!$C$20:$K$20) -> 9 | D8: =COUNTIF('Infrastructure and Systems'!C25:K25,"No Issue Reported")+COUNTIF('Infrastructure and Systems'!C25:K25,"Partially Working")*0.7+COUNTIF('Infrastructure and Systems'!C25:K25,"Total Failure")*0.3 -> 9 | E8: =D8/C8 -> 1
A9: ='Infrastructure and Systems'!A10 -> 7 | B9: ='Infrastructure and Systems'!B10 -> Electronic Weighment Solution (EWS Version) | C9: =COUNTA('Infrastructure and Systems'!$C$20:$K$20) -> 9 | D9: =COUNTIF('Infrastructure and Systems'!C26:K26,"No Issue Reported")+COUNTIF('Infrastructure and Systems'!C26:K26,"Partially Working")*0.7+COUNTIF('Infrastructure and Systems'!C26:K26,"Total Failure")*0.3 -> 9 | E9: =D9/C9 -> 1
A10: ='Infrastructure and Systems'!#REF! -> #REF! | B10: ='Infrastructure and Systems'!#REF! -> #REF! | C10: =COUNTA('Infrastructure and Systems'!$C$20:$K$20) -> 9 | D10: =COUNTIF('Infrastructure and Systems'!C27:K27,"No Issue Reported")+COUNTIF('Infrastructure and Systems'!C27:K27,"Partially Working")*0.7+COUNTIF('Infrastructure and Systems'!C27:K27,"Total Failure")*0.3 -> 9 | E10: =D10/C10 -> 1
B11: Average | E11: =AVERAGE(E4:E10) -> 1
B13: ChaiPro
A14: No | B14: Service | C14: No of Factories | D14: Region 2 | E14: % Uptime Service | F14: Factories Affected | G14: Issue
A15: 1 | B15: Chaipro Financials | C15: =COUNTA('Infrastructure and Systems'!$C$20:$K$20) -> 9 | D15: =COUNTIF('Chaipro-SAP'!#REF!,"SAP")*1+COUNTIF('Chaipro-SAP'!#REF!,"2.5.5.7")*1+COUNTIF('Chaipro-SAP'!#REF!,"Other version Working")*0.8+COUNTIF('Chaipro-SAP'!#REF!,"2.5.5.7 With Issues")*0.6+COUNTIF('Chaipro-SAP'!#REF!,"Other version With Issues")*0.4 + COUNTIF('Chaipro-SAP'!C3:N3,"None")*0.25 -> #REF! | E15: =D15/C15 -> #REF!
A16: 2 | B16: Chaipro Factory/TVAP | C16: =COUNTA('Infrastructure and Systems'!$C$20:$K$20) -> 9 | D16: =COUNTIF('Chaipro-SAP'!#REF!,"SAP")*1+COUNTIF('Chaipro-SAP'!#REF!,"2.5.5.7")*1+COUNTIF('Chaipro-SAP'!#REF!,"Other version Working")*0.8+COUNTIF('Chaipro-SAP'!#REF!,"2.5.5.7 With Issues")*0.6+COUNTIF('Chaipro-SAP'!#REF!,"Other version With Issues")*0.4 + COUNTIF('Chaipro-SAP'!C4:N4,"None")*0.25 -> #REF! | E16: =D16/C16 -> #REF!
A17: 3 | B17: Chaipro Farmers | C17: =COUNTA('Infrastructure and Systems'!$C$20:$K$20) -> 9 | D17: =COUNTIF('Chaipro-SAP'!#REF!,"2.8.0.0")*1+COUNTIF('Chaipro-SAP'!#REF!,"Other version Working")*0.8+COUNTIF('Chaipro-SAP'!#REF!,"2.8.0.0 With Issues")*0.6+COUNTIF('Chaipro-SAP'!#REF!,"Other version With Issues")*0.4 + COUNTIF('Chaipro-SAP'!C5:N5,"None")*0.25 -> #REF! | E17: =D17/C17 -> #REF!
A18: 4 | B18: Chaipro Fleet | C18: =COUNTA('Infrastructure and Systems'!$C$20:$K$20) -> 9 | D18: =COUNTIF('Chaipro-SAP'!#REF!,"3.2.5.1")*1+COUNTIF('Chaipro-SAP'!#REF!,"Other version Working")*0.8+COUNTIF('Chaipro-SAP'!#REF!,"3.2.5.1 With Issues")*0.6+COUNTIF('Chaipro-SAP'!#REF!,"Other version With Issues")*0.4 + COUNTIF('Chaipro-SAP'!#REF!,"None")*0.25 -> #REF! | E18: =D18/C18 -> #REF!
A19: 6 | B19: KTDA Replicator | C19: =COUNTA('Infrastructure and Systems'!$C$20:$K$20) -> 9 | D19: =COUNTIF('Chaipro-SAP'!#REF!,"Working")*1+COUNTIF('Chaipro-SAP'!#REF!,"Working With Issues")*0.5 -> #REF! | E19: =D19/C19 -> #REF!
A20: 7 | B20: Chai Data | C20: =COUNTA('Infrastructure and Systems'!$C$20:$K$20) -> 9 | D20: =COUNTIF('Chaipro-SAP'!#REF!,"1.0.0.3")*1+COUNTIF('Chaipro-SAP'!#REF!,"Other version Working")*0.8+COUNTIF('Chaipro-SAP'!#REF!,"1.0.0.3 With Issues")*0.6+COUNTIF('Chaipro-SAP'!#REF!,"Other version With Issues")*0.4 + COUNTIF('Chaipro-SAP'!B8:L8,"None")*0.25 -> #REF! | E20: =D20/C20 -> #REF!
A21: 8 | B21: Chai POS | C21: =COUNTA('Infrastructure and Systems'!$C$20:$K$20) -> 9 | D21: =COUNTIF('Chaipro-SAP'!#REF!,"2.2")*1+COUNTIF('Chaipro-SAP'!#REF!,"Other version Working")*0.8+COUNTIF('Chaipro-SAP'!#REF!,"2.2 With Issues")*0.6+COUNTIF('Chaipro-SAP'!#REF!,"Other version With Issues")*0.4 + COUNTIF('Chaipro-SAP'!#REF!,"None")*0.25 -> #REF! | E21: =D21/C21 -> #REF!
B22: Average | E22: =AVERAGE(E15:E21) -> #REF!
B24: Inventory
A25: No | B25: Service | C25: No of Factories | D25: Region 2 | E25: % Uptime Service | F25: Factories Affected | G25: Issue
A26: 1 | B26: Network Equipments (e.g. Switch, 2, Functional, any additional details) | C26: =COUNTA('Infrastructure and Systems'!$C$20:$K$20) -> 9 | D26: =COUNTIF('ICT Inventory'!#REF!,"No Issue Reported")+COUNTIF('ICT Inventory'!#REF!,"Partially Working")*0.7+COUNTIF('ICT Inventory'!#REF!,"Total Failure")*0.3 -> #REF! | E26: =D26/C26 -> #REF!
A27: 2 | B27: Software (e.g. third party software) etc | C27: =COUNTA('Infrastructure and Systems'!$C$20:$K$20) -> 9 | D27: =COUNTIF('ICT Inventory'!#REF!,"No Issue Reported")+COUNTIF('ICT Inventory'!#REF!,"Partially Working")*0.7+COUNTIF('ICT Inventory'!#REF!,"Total Failure")*0.3 -> #REF! | E27: =D27/C27 -> #REF!
A28: 3 | B28: Hardware (e.g. Servers, PCs, Laptops, UPS, DAs, Printers, Scanners, ESD, Fiscal Printers, Tablets) | C28: =COUNTA('Infrastructure and Systems'!$C$20:$K$20) -> 9 | D28: =COUNTIF('ICT Inventory'!#REF!,"No Issue Reported")+COUNTIF('ICT Inventory'!#REF!,"Partially Working")*0.7+COUNTIF('ICT Inventory'!#REF!,"Total Failure")*0.3 -> #REF! | E28: =D28/C28 -> #REF!
A29: 4 | B29: Other Equipment (please specify) | C29: =COUNTA('Infrastructure and Systems'!$C$20:$K$20) -> 9 | D29: =COUNTIF('ICT Inventory'!#REF!,"No Issue Reported")+COUNTIF('ICT Inventory'!#REF!,"Partially Working")*0.7+COUNTIF('ICT Inventory'!#REF!,"Total Failure")*0.3 -> #REF! | E29: =D29/C29 -> #REF!
B30: Average | E30: =AVERAGE(E26:E29) -> #REF!
B32: BCP
A33: No | B33: Service | C33: No of Factories | D33: Region 2 | E33: % Uptime Service | F33: Factories Affected | G33: Issue
A34: 1 | B34: Business Continuity Mechanism e.g. Backups | C34: =COUNTA(BCP!#REF!) -> 1 | D34: =COUNTA(BCP!#REF!) -> 1 | E34: =D34/C34 -> 1
B35: Average | E35: =AVERAGE(E34) -> 1
B38: PURCHASES
A39: No | B39: Service | C39: No of Factories | D39: Total Cost | E39: Cost vs budget | F39: Factories Affected | G39: Issue
A40: 1 | B40: Purchases | C40: =COUNTA('ICT Cost'!$B$13:$J$13) -> 9 | D40: ='ICT Cost'!J18 -> 415,810
B41: Average

Sheet R3
B1: Region 3
B2: Infrastructure
A3: ='Infrastructure and Systems'!A3 -> No. | B3: Service | C3: No of Factories | D3: Region 3 | E3: % Uptime Service | F3: Factories Having Issues | G3: Summary of Issues | H3: Duration (days) | I3: Tickets Raised
A4: ='Infrastructure and Systems'!A4 -> 1 | B4: ='Infrastructure and Systems'!B4 -> Local Area Network (LAN) | C4: =COUNTA('Infrastructure and Systems'!$C$37:$J$37) -> 8 | D4: =COUNTIF('Infrastructure and Systems'!#REF!,"No Issue Reported")+COUNTIF('Infrastructure and Systems'!#REF!,"Partially Working")*0.7+COUNTIF('Infrastructure and Systems'!#REF!,"Total Failure")*0.3 -> #REF! | E4: =D4/C4 -> #REF!
A5: ='Infrastructure and Systems'!A5 -> 2 | B5: ='Infrastructure and Systems'!B5 -> Wide Area Network (WAN) | C5: =COUNTA('Infrastructure and Systems'!$C$37:$J$37) -> 8 | D5: =COUNTIF('Infrastructure and Systems'!C38:J38,"No Issue Reported")+COUNTIF('Infrastructure and Systems'!C38:J38,"Partially Working")*0.7+COUNTIF('Infrastructure and Systems'!C38:J38,"Total Failure")*0.3 -> 0 | E5: =D5/C5 -> 0
A6: ='Infrastructure and Systems'!A7 -> 4 | B6: ='Infrastructure and Systems'!B7 -> Firewall | C6: =COUNTA('Infrastructure and Systems'!$C$37:$J$37) -> 8 | D6: =COUNTIF('Infrastructure and Systems'!C39:J39,"No Issue Reported")+COUNTIF('Infrastructure and Systems'!C39:J39,"Partially Working")*0.7+COUNTIF('Infrastructure and Systems'!C39:J39,"Total Failure")*0.3 -> 0 | E6: =IF('Infrastructure and Systems'!C7="Internet slow even sometimes not available",(D6/C6)/2,(D6/C6)) -> 0
A7: ='Infrastructure and Systems'!A8 -> 5 | B7: ='Infrastructure and Systems'!B8 -> E-Mail Server | C7: =COUNTA('Infrastructure and Systems'!$C$37:$J$37) -> 8 | D7: =COUNTIF('Infrastructure and Systems'!C40:J40,"Domino in use")*1+COUNTIF('Infrastructure and Systems'!C40:J40,"Exchange in Use")*0.8+COUNTIF('Infrastructure and Systems'!C40:J40,"Domino In Use-Issues")*0.6+COUNTIF('Infrastructure and Systems'!C24:K24,"Exchange In Use-Issues")*0.4+COUNTIF('Infrastructure and Systems'!C24:K24,"None")*0.2 -> 0 | E7: =D7/C7 -> 0
A8: ='Infrastructure and Systems'!A9 -> 6 | B8: ='Infrastructure and Systems'!B9 -> Business Servers (EWS, Chaipro) | C8: =COUNTA('Infrastructure and Systems'!$C$37:$J$37) -> 8 | D8: =COUNTIF('Infrastructure and Systems'!C41:J41,"No Issue Reported")+COUNTIF('Infrastructure and Systems'!C41:J41,"Partially Working")*0.7+COUNTIF('Infrastructure and Systems'!C41:J41,"Total Failure")*0.3 -> 0 | E8: =D8/C8 -> 0
A9: ='Infrastructure and Systems'!A10 -> 7 | B9: ='Infrastructure and Systems'!B10 -> Electronic Weighment Solution (EWS Version) | C9: =COUNTA('Infrastructure and Systems'!$C$37:$J$37) -> 8 | D9: =COUNTIF('Infrastructure and Systems'!C42:J42,"No Issue Reported")+COUNTIF('Infrastructure and Systems'!C42:J42,"Partially Working")*0.7+COUNTIF('Infrastructure and Systems'!C42:J42,"Total Failure")*0.3 -> 0 | E9: =D9/C9 -> 0
A10: ='Infrastructure and Systems'!#REF! -> #REF! | B10: ='Infrastructure and Systems'!#REF! -> #REF! | C10: =COUNTA('Infrastructure and Systems'!$C$37:$J$37) -> 8 | D10: =COUNTIF('Infrastructure and Systems'!C43:J43,"No Issue Reported")+COUNTIF('Infrastructure and Systems'!C43:J43,"Partially Working")*0.7+COUNTIF('Infrastructure and Systems'!C43:J43,"Total Failure")*0.3 -> 0 | E10: =D10/C10 -> 0
B11: Average | E11: =AVERAGE(E4:E10) -> #REF!
B13: ChaiPro
A14: No | B14: Service | C14: No of Factories | D14: Region 3 | E14: % Uptime Service | F14: Factories Affected | G14: Issue
A15: 1 | B15: Chaipro Financials | C15: =COUNTA('Infrastructure and Systems'!$C$37:$J$37) -> 8 | D15: =COUNTIF('Chaipro-SAP'!C28:J28,"2.5.5.7")*1+COUNTIF('Chaipro-SAP'!C28:J28,"2.5.5.8")*1+COUNTIF('Chaipro-SAP'!C28:J28,"2.5.5.9")*1+COUNTIF('Chaipro-SAP'!C28:J28,"2.5.6.0")*1+COUNTIF('Chaipro-SAP'!C28:J28,"SAP")*1+COUNTIF('Chaipro-SAP'!C28:J28,"Other version Working")*0.8+COUNTIF('Chaipro-SAP'!C28:J28,"2.5.5.7 With Issues")*0.6+COUNTIF('Chaipro-SAP'!C28:J28,"Other version With Issues")*0.4 + COUNTIF('Chaipro-SAP'!C28:J28,"None")*0.25 -> 2 | E15: =D15/C15 -> 0.25
A16: 2 | B16: Chaipro Factory/TVAP | C16: =COUNTA('Infrastructure and Systems'!$C$37:$J$37) -> 8 | D16: =COUNTIF('Chaipro-SAP'!C29:J29,"2.5.2.5")*1+COUNTIF('Chaipro-SAP'!C29:J29,"2.5.2.7")*1+COUNTIF('Chaipro-SAP'!C29:J29,"SAP")*1+COUNTIF('Chaipro-SAP'!C29:J29,"Other version Working")*0.8+COUNTIF('Chaipro-SAP'!C29:J29,"2.5.2.5 With Issues")*0.6+COUNTIF('Chaipro-SAP'!C29:J29,"Other version With Issues")*0.4 + COUNTIF('Chaipro-SAP'!C29:J29,"None")*0.25 -> 2 | E16: =D16/C16 -> 0.25
A17: 3 | B17: Chaipro Farmers | C17: =COUNTA('Infrastructure and Systems'!$C$37:$J$37) -> 8 | D17: =COUNTIF('Chaipro-SAP'!C30:J30,"3.0.0.1")*1+COUNTIF('Chaipro-SAP'!C30:J30,"2.8.0.0")*1+COUNTIF('Chaipro-SAP'!C30:J30,"Other version Working")*0.8+COUNTIF('Chaipro-SAP'!C30:J30,"2.8.0.0 With Issues")*0.6+COUNTIF('Chaipro-SAP'!C30:J30,"Other version With Issues")*0.4 + COUNTIF('Chaipro-SAP'!C30:J30,"None")*0.25 -> 2 | E17: =D17/C17 -> 0.25
A18: 4 | B18: Chaipro Fleet | C18: =COUNTA('Infrastructure and Systems'!$C$37:$J$37) -> 8 | D18: =COUNTIF('Chaipro-SAP'!C31:J31,"3.2.5.1")*1+COUNTIF('Chaipro-SAP'!C31:J31,"Other version Working")*0.8+COUNTIF('Chaipro-SAP'!C31:J31,"3.2.5.1 With Issues")*0.6+COUNTIF('Chaipro-SAP'!C31:J31,"Other version With Issues")*0.4 + COUNTIF('Chaipro-SAP'!C31:J31,"None")*0.25 -> 2 | E18: =D18/C18 -> 0.25
A19: 6 | B19: KTDA Replicator | C19: =COUNTA('Infrastructure and Systems'!$C$37:$J$37) -> 8 | D19: =COUNTIF('Chaipro-SAP'!C32:J32,"Working")*1+COUNTIF('Chaipro-SAP'!C32:J32,"Working With Issues")*0.5 -> 0 | E19: =D19/C19 -> 0
A20: 7 | B20: Chai Data | C20: =COUNTA('Infrastructure and Systems'!$C$37:$J$37) -> 8 | D20: =COUNTIF('Chaipro-SAP'!C33:J33,"1.0.0.3")*1+COUNTIF('Chaipro-SAP'!C33:J33,"Other version Working")*0.8+COUNTIF('Chaipro-SAP'!C22:J33,"1.0.0.3 With Issues")*0.6+COUNTIF('Chaipro-SAP'!C33:J33,"Other version With Issues")*0.4 + COUNTIF('Chaipro-SAP'!B8:L8,"None")*0.25 -> 0 | E20: =D20/C20 -> 0
